[2023-09-05 08:09:29,916] {taskinstance.py:1159} INFO - Dependencies all met for <TaskInstance: 1_init_once_seed_data.load_seed_data_once scheduled__2020-08-01T00:00:00+00:00 [queued]>
[2023-09-05 08:09:29,921] {taskinstance.py:1159} INFO - Dependencies all met for <TaskInstance: 1_init_once_seed_data.load_seed_data_once scheduled__2020-08-01T00:00:00+00:00 [queued]>
[2023-09-05 08:09:29,922] {taskinstance.py:1356} INFO - 
--------------------------------------------------------------------------------
[2023-09-05 08:09:29,922] {taskinstance.py:1357} INFO - Starting attempt 1 of 1
[2023-09-05 08:09:29,922] {taskinstance.py:1358} INFO - 
--------------------------------------------------------------------------------
[2023-09-05 08:09:29,931] {taskinstance.py:1377} INFO - Executing <Task(BashOperator): load_seed_data_once> on 2020-08-01 00:00:00+00:00
[2023-09-05 08:09:29,935] {standard_task_runner.py:52} INFO - Started process 505 to run task
[2023-09-05 08:09:29,939] {standard_task_runner.py:79} INFO - Running: ['***', 'tasks', 'run', '1_init_once_seed_data', 'load_seed_data_once', 'scheduled__2020-08-01T00:00:00+00:00', '--job-id', '3', '--raw', '--subdir', 'DAGS_FOLDER/init.py', '--cfg-path', '/tmp/tmp_chlc7oi', '--error-file', '/tmp/tmp3imey1jz']
[2023-09-05 08:09:29,939] {standard_task_runner.py:80} INFO - Job 3: Subtask load_seed_data_once
[2023-09-05 08:09:29,984] {task_command.py:369} INFO - Running <TaskInstance: 1_init_once_seed_data.load_seed_data_once scheduled__2020-08-01T00:00:00+00:00 [running]> on host 3d5dd07fd9f5
[2023-09-05 08:09:30,059] {taskinstance.py:1571} INFO - Exporting the following env vars:
AIRFLOW_CTX_DAG_OWNER=***
AIRFLOW_CTX_DAG_ID=1_init_once_seed_data
AIRFLOW_CTX_TASK_ID=load_seed_data_once
AIRFLOW_CTX_EXECUTION_DATE=2020-08-01T00:00:00+00:00
AIRFLOW_CTX_TRY_NUMBER=1
AIRFLOW_CTX_DAG_RUN_ID=scheduled__2020-08-01T00:00:00+00:00
[2023-09-05 08:09:30,060] {subprocess.py:62} INFO - Tmp dir root location: 
 /tmp
[2023-09-05 08:09:30,061] {subprocess.py:74} INFO - Running command: ['bash', '-c', 'cd /dbt && dbt seed --profiles-dir .']
[2023-09-05 08:09:30,073] {subprocess.py:85} INFO - Output:
[2023-09-05 08:09:30,077] {subprocess.py:92} INFO - bash: line 1: dbt: command not found
[2023-09-05 08:09:30,077] {subprocess.py:96} INFO - Command exited with return code 127
[2023-09-05 08:09:30,091] {taskinstance.py:1889} ERROR - Task failed with exception
Traceback (most recent call last):
  File "/home/airflow/.local/lib/python3.7/site-packages/airflow/operators/bash.py", line 195, in execute
    f'Bash command failed. The command returned a non-zero exit code {result.exit_code}.'
airflow.exceptions.AirflowException: Bash command failed. The command returned a non-zero exit code 127.
[2023-09-05 08:09:30,094] {taskinstance.py:1400} INFO - Marking task as FAILED. dag_id=1_init_once_seed_data, task_id=load_seed_data_once, execution_date=20200801T000000, start_date=20230905T080929, end_date=20230905T080930
[2023-09-05 08:09:30,103] {standard_task_runner.py:97} ERROR - Failed to execute job 3 for task load_seed_data_once (Bash command failed. The command returned a non-zero exit code 127.; 505)
[2023-09-05 08:09:30,153] {local_task_job.py:156} INFO - Task exited with return code 1
[2023-09-05 08:09:30,180] {local_task_job.py:273} INFO - 0 downstream tasks scheduled from follow-on schedule check
